Workbook

Sheet QALS - Inspection Lot Record
A1: InspectionLot | B1: Plant | C1: InspType | D1: ObjectNumber | E1: LotCreated | F1: LotCreationTime | G1: CreatedBy | H1: StartDate | I1: StartTime | J1: EndDate | K1: EndTime | L1: TasklistType | M1: ProcessOrder | N1: Product | O1: ProductDescription | P1: Batch
A2: 40000002501 | B2: 1010 | C2: 4 | D2: QL040000003101 | E2: =E3 -> 45870 | F2: =TIME(RANDBETWEEN(12,22), RANDBETWEEN(0,59), RANDBETWEEN(0,59)) -> 0.69314815 | G2: TP397880 | H2: =E2 -> 45870 | I2: =F2 -> 0.69314815 | J2: =E2 -> 45870 | K2: =I2+TIME(1,RANDBETWEEN(25,50),RANDBETWEEN(0,59)) -> 0.76893519 | L2: Q | M2: 1004511 | N2: FG0001SEG | O2: {=_xlfn.IFS(N2="FG2020US1", "Ibuprofen Tablets (100 MG)", N2="FG0001SEG", "Metformin Tablets (100 MG)", N2="FG0002SEG", "Metformin Tablets (200 MG)", N2="FG0003SEG", "Metformin Tablets (500 MG)", N2="FG00UDI4", "Aspirin Tablets (500 MG)")} -> Metformin Tablets (100 MG) | P2: 4001
A3: 40000002502 | B3: 1010 | C3: 4 | D3: QL040000003102 | E3: =E4-1 -> 45870 | F3: =TIME(RANDBETWEEN(0,10), RANDBETWEEN(0,59), RANDBETWEEN(0,59)) -> 0.098055556 | G3: YA284176 | H3: =E3 -> 45870 | I3: =F3 -> 0.098055556 | J3: =E3 -> 45870 | K3: =I3+TIME(1,RANDBETWEEN(25,50),RANDBETWEEN(0,59)) -> 0.15883102 | L3: Q | M3: 1004512 | N3: FG2020US1 | O3: {=_xlfn.IFS(N3="FG2020US1", "Ibuprofen Tablets (100 MG)", N3="FG0001SEG", "Metformin Tablets (100 MG)", N3="FG0002SEG", "Metformin Tablets (200 MG)", N3="FG0003SEG", "Metformin Tablets (500 MG)", N3="FG00UDI4", "Aspirin Tablets (500 MG)")} -> Ibuprofen Tablets (100 MG) | P3: 4002
A4: 40000002503 | B4: 1010 | C4: 4 | D4: QL040000003103 | E4: =E5 -> 45871 | F4: =TIME(RANDBETWEEN(12,22), RANDBETWEEN(0,59), RANDBETWEEN(0,59)) -> 0.90376157 | G4: ZK384180 | H4: =E4 -> 45871 | I4: =F4 -> 0.90376157 | J4: =E4 -> 45871 | K4: =I4+TIME(1,RANDBETWEEN(25,50),RANDBETWEEN(0,59)) -> 0.97219907 | L4: Q | M4: 1004513 | N4: FG0001SEG | O4: {=_xlfn.IFS(N4="FG2020US1", "Ibuprofen Tablets (100 MG)", N4="FG0001SEG", "Metformin Tablets (100 MG)", N4="FG0002SEG", "Metformin Tablets (200 MG)", N4="FG0003SEG", "Metformin Tablets (500 MG)", N4="FG00UDI4", "Aspirin Tablets (500 MG)")} -> Metformin Tablets (100 MG) | P4: 4003
A5: 40000002504 | B5: 1010 | C5: 4 | D5: QL040000003104 | E5: =E6-1 -> 45871 | F5: =TIME(RANDBETWEEN(0,10), RANDBETWEEN(0,59), RANDBETWEEN(0,59)) -> 0.098969907 | G5: YA284176 | H5: =E5 -> 45871 | I5: =F5 -> 0.098969907 | J5: =E5 -> 45871 | K5: =I5+TIME(1,RANDBETWEEN(25,50),RANDBETWEEN(0,59)) -> 0.16030093 | L5: Q | M5: 1004514 | N5: FG0001SEG | O5: {=_xlfn.IFS(N5="FG2020US1", "Ibuprofen Tablets (100 MG)", N5="FG0001SEG", "Metformin Tablets (100 MG)", N5="FG0002SEG", "Metformin Tablets (200 MG)", N5="FG0003SEG", "Metformin Tablets (500 MG)", N5="FG00UDI4", "Aspirin Tablets (500 MG)")} -> Metformin Tablets (100 MG) | P5: 4004
A6: 40000002505 | B6: 1010 | C6: 4 | D6: QL040000003105 | E6: =E7 -> 45872 | F6: =TIME(RANDBETWEEN(12,22), RANDBETWEEN(0,59), RANDBETWEEN(0,59)) -> 0.54824074 | G6: TP397880 | H6: =E6 -> 45872 | I6: =F6 -> 0.54824074 | J6: =E6 -> 45872 | K6: =I6+TIME(1,RANDBETWEEN(25,50),RANDBETWEEN(0,59)) -> 0.61037037 | L6: Q | M6: 1004515 | N6: FG0003SEG | O6: {=_xlfn.IFS(N6="FG2020US1", "Ibuprofen Tablets (100 MG)", N6="FG0001SEG", "Metformin Tablets (100 MG)", N6="FG0002SEG", "Metformin Tablets (200 MG)", N6="FG0003SEG", "Metformin Tablets (500 MG)", N6="FG00UDI4", "Aspirin Tablets (500 MG)")} -> Metformin Tablets (500 MG) | P6: 4005
A7: 40000002506 | B7: 1010 | C7: 4 | D7: QL040000003106 | E7: =E8-1 -> 45872 | F7: =TIME(RANDBETWEEN(0,10), RANDBETWEEN(0,59), RANDBETWEEN(0,59)) -> 0.14915509 | G7: YA284176 | H7: =E7 -> 45872 | I7: =F7 -> 0.14915509 | J7: =E7 -> 45872 | K7: =I7+TIME(1,RANDBETWEEN(25,50),RANDBETWEEN(0,59)) -> 0.22229167 | L7: Q | M7: 1004516 | N7: FG0003SEG | O7: {=_xlfn.IFS(N7="FG2020US1", "Ibuprofen Tablets (100 MG)", N7="FG0001SEG", "Metformin Tablets (100 MG)", N7="FG0002SEG", "Metformin Tablets (200 MG)", N7="FG0003SEG", "Metformin Tablets (500 MG)", N7="FG00UDI4", "Aspirin Tablets (500 MG)")} -> Metformin Tablets (500 MG) | P7: 4006
A8: 40000002507 | B8: 1010 | C8: 4 | D8: QL040000003107 | E8: =E9 -> 45873 | F8: =TIME(RANDBETWEEN(12,22), RANDBETWEEN(0,59), RANDBETWEEN(0,59)) -> 0.75422454 | G8: AB406550 | H8: =E8 -> 45873 | I8: =F8 -> 0.75422454 | J8: =E8 -> 45873 | K8: =I8+TIME(1,RANDBETWEEN(25,50),RANDBETWEEN(0,59)) -> 0.81810185 | L8: Q | M8: 1004517 | N8: FG00UDI4 | O8: {=_xlfn.IFS(N8="FG2020US1", "Ibuprofen Tablets (100 MG)", N8="FG0001SEG", "Metformin Tablets (100 MG)", N8="FG0002SEG", "Metformin Tablets (200 MG)", N8="FG0003SEG", "Metformin Tablets (500 MG)", N8="FG00UDI4", "Aspirin Tablets (500 MG)")} -> Aspirin Tablets (500 MG) | P8: 4007
A9: 40000002508 | B9: 1010 | C9: 4 | D9: QL040000003108 | E9: =E10-1 -> 45873 | F9: =TIME(RANDBETWEEN(0,10), RANDBETWEEN(0,59), RANDBETWEEN(0,59)) -> 0.042106481 | G9: YA284176 | H9: =E9 -> 45873 | I9: =F9 -> 0.042106481 | J9: =E9 -> 45873 | K9: =I9+TIME(1,RANDBETWEEN(25,50),RANDBETWEEN(0,59)) -> 0.11483796 | L9: Q | M9: 1004518 | N9: FG0003SEG | O9: {=_xlfn.IFS(N9="FG2020US1", "Ibuprofen Tablets (100 MG)", N9="FG0001SEG", "Metformin Tablets (100 MG)", N9="FG0002SEG", "Metformin Tablets (200 MG)", N9="FG0003SEG", "Metformin Tablets (500 MG)", N9="FG00UDI4", "Aspirin Tablets (500 MG)")} -> Metformin Tablets (500 MG) | P9: 4008
A10: 40000002509 | B10: 1010 | C10: 4 | D10: QL040000003109 | E10: =E11 -> 45874 | F10: =TIME(RANDBETWEEN(12,22), RANDBETWEEN(0,59), RANDBETWEEN(0,59)) -> 0.52502315 | G10: ZK384180 | H10: =E10 -> 45874 | I10: =F10 -> 0.52502315 | J10: =E10 -> 45874 | K10: =I10+TIME(1,RANDBETWEEN(25,50),RANDBETWEEN(0,59)) -> 0.58457176 | L10: Q | M10: 1004519 | N10: FG0002SEG | O10: {=_xlfn.IFS(N10="FG2020US1", "Ibuprofen Tablets (100 MG)", N10="FG0001SEG", "Metformin Tablets (100 MG)", N10="FG0002SEG", "Metformin Tablets (200 MG)", N10="FG0003SEG", "Metformin Tablets (500 MG)", N10="FG00UDI4", "Aspirin Tablets (500 MG)")} -> Metformin Tablets (200 MG) | P10: 4009
A11: 40000002510 | B11: 1010 | C11: 4 | D11: QL040000003110 | E11: =E12-1 -> 45874 | F11: =TIME(RANDBETWEEN(0,10), RANDBETWEEN(0,59), RANDBETWEEN(0,59)) -> 0.21421296 | G11: GC197258 | H11: =E11 -> 45874 | I11: =F11 -> 0.21421296 | J11: =E11 -> 45874 | K11: =I11+TIME(1,RANDBETWEEN(25,50),RANDBETWEEN(0,59)) -> 0.28644676 | L11: Q | M11: 1004520 | N11: FG0001SEG | O11: {=_xlfn.IFS(N11="FG2020US1", "Ibuprofen Tablets (100 MG)", N11="FG0001SEG", "Metformin Tablets (100 MG)", N11="FG0002SEG", "Metformin Tablets (200 MG)", N11="FG0003SEG", "Metformin Tablets (500 MG)", N11="FG00UDI4", "Aspirin Tablets (500 MG)")} -> Metformin Tablets (100 MG) | P11: 4010
A12: 40000002511 | B12: 1010 | C12: 4 | D12: QL040000003111 | E12: =E13 -> 45875 | F12: =TIME(RANDBETWEEN(12,22), RANDBETWEEN(0,59), RANDBETWEEN(0,59)) -> 0.83722222 | G12: TP397880 | H12: =E12 -> 45875 | I12: =F12 -> 0.83722222 | J12: =E12 -> 45875 | K12: =I12+TIME(1,RANDBETWEEN(25,50),RANDBETWEEN(0,59)) -> 0.89800926 | L12: Q | M12: 1004521 | N12: FG2020US1 | O12: {=_xlfn.IFS(N12="FG2020US1", "Ibuprofen Tablets (100 MG)", N12="FG0001SEG", "Metformin Tablets (100 MG)", N12="FG0002SEG", "Metformin Tablets (200 MG)", N12="FG0003SEG", "Metformin Tablets (500 MG)", N12="FG00UDI4", "Aspirin Tablets (500 MG)")} -> Ibuprofen Tablets (100 MG) | P12: 4011
A13: 40000002512 | B13: 1010 | C13: 4 | D13: QL040000003112 | E13: =E14-1 -> 45875 | F13: =TIME(RANDBETWEEN(0,10), RANDBETWEEN(0,59), RANDBETWEEN(0,59)) -> 0.105625 | G13: TG509538 | H13: =E13 -> 45875 | I13: =F13 -> 0.105625 | J13: =E13 -> 45875 | K13: =I13+TIME(1,RANDBETWEEN(25,50),RANDBETWEEN(0,59)) -> 0.17284722 | L13: Q | M13: 1004522 | N13: FG0001SEG | O13: {=_xlfn.IFS(N13="FG2020US1", "Ibuprofen Tablets (100 MG)", N13="FG0001SEG", "Metformin Tablets (100 MG)", N13="FG0002SEG", "Metformin Tablets (200 MG)", N13="FG0003SEG", "Metformin Tablets (500 MG)", N13="FG00UDI4", "Aspirin Tablets (500 MG)")} -> Metformin Tablets (100 MG) | P13: 4012
A14: 40000002513 | B14: 1010 | C14: 4 | D14: QL040000003113 | E14: =E15 -> 45876 | F14: =TIME(RANDBETWEEN(12,22), RANDBETWEEN(0,59), RANDBETWEEN(0,59)) -> 0.76216435 | G14: ZK384180 | H14: =E14 -> 45876 | I14: =F14 -> 0.76216435 | J14: =E14 -> 45876 | K14: =I14+TIME(1,RANDBETWEEN(25,50),RANDBETWEEN(0,59)) -> 0.82128472 | L14: Q | M14: 1004523 | N14: FG0003SEG | O14: {=_xlfn.IFS(N14="FG2020US1", "Ibuprofen Tablets (100 MG)", N14="FG0001SEG", "Metformin Tablets (100 MG)", N14="FG0002SEG", "Metformin Tablets (200 MG)", N14="FG0003SEG", "Metformin Tablets (500 MG)", N14="FG00UDI4", "Aspirin Tablets (500 MG)")} -> Metformin Tablets (500 MG) | P14: 4013
A15: 40000002514 | B15: 1010 | C15: 4 | D15: QL040000003114 | E15: =E16-1 -> 45876 | F15: =TIME(RANDBETWEEN(0,10), RANDBETWEEN(0,59), RANDBETWEEN(0,59)) -> 0.16636574 | G15: YA284176 | H15: =E15 -> 45876 | I15: =F15 -> 0.16636574 | J15: =E15 -> 45876 | K15: =I15+TIME(1,RANDBETWEEN(25,50),RANDBETWEEN(0,59)) -> 0.23636574 | L15: Q | M15: 1004524 | N15: FG2020US1 | O15: {=_xlfn.IFS(N15="FG2020US1", "Ibuprofen Tablets (100 MG)", N15="FG0001SEG", "Metformin Tablets (100 MG)", N15="FG0002SEG", "Metformin Tablets (200 MG)", N15="FG0003SEG", "Metformin Tablets (500 MG)", N15="FG00UDI4", "Aspirin Tablets (500 MG)")} -> Ibuprofen Tablets (100 MG) | P15: 4014
A16: 40000002515 | B16: 1010 | C16: 4 | D16: QL040000003115 | E16: =E17 -> 45877 | F16: =TIME(RANDBETWEEN(12,22), RANDBETWEEN(0,59), RANDBETWEEN(0,59)) -> 0.9177662 | G16: TP397880 | H16: =E16 -> 45877 | I16: =F16 -> 0.9177662 | J16: =E16 -> 45877 | K16: =I16+TIME(1,RANDBETWEEN(25,50),RANDBETWEEN(0,59)) -> 0.99177083 | L16: Q | M16: 1004525 | N16: FG2020US1 | O16: {=_xlfn.IFS(N16="FG2020US1", "Ibuprofen Tablets (100 MG)", N16="FG0001SEG", "Metformin Tablets (100 MG)", N16="FG0002SEG", "Metformin Tablets (200 MG)", N16="FG0003SEG", "Metformin Tablets (500 MG)", N16="FG00UDI4", "Aspirin Tablets (500 MG)")} -> Ibuprofen Tablets (100 MG) | P16: 4015
A17: 40000002516 | B17: 1010 | C17: 4 | D17: QL040000003116 | E17: =E18-1 -> 45877 | F17: =TIME(RANDBETWEEN(0,10), RANDBETWEEN(0,59), RANDBETWEEN(0,59)) -> 0.069143519 | G17: YA284176 | H17: =E17 -> 45877 | I17: =F17 -> 0.069143519 | J17: =E17 -> 45877 | K17: =I17+TIME(1,RANDBETWEEN(25,50),RANDBETWEEN(0,59)) -> 0.14555556 | L17: Q | M17: 1004526 | N17: FG0002SEG | O17: {=_xlfn.IFS(N17="FG2020US1", "Ibuprofen Tablets (100 MG)", N17="FG0001SEG", "Metformin Tablets (100 MG)", N17="FG0002SEG", "Metformin Tablets (200 MG)", N17="FG0003SEG", "Metformin Tablets (500 MG)", N17="FG00UDI4", "Aspirin Tablets (500 MG)")} -> Metformin Tablets (200 MG) | P17: 4016
A18: 40000002517 | B18: 1010 | C18: 4 | D18: QL040000003117 | E18: =E19 -> 45878 | F18: =TIME(RANDBETWEEN(12,22), RANDBETWEEN(0,59), RANDBETWEEN(0,59)) -> 0.70297454 | G18: ZK384180 | H18: =E18 -> 45878 | I18: =F18 -> 0.70297454 | J18: =E18 -> 45878 | K18: =I18+TIME(1,RANDBETWEEN(25,50),RANDBETWEEN(0,59)) -> 0.76347222 | L18: Q | M18: 1004527 | N18: FG0002SEG | O18: {=_xlfn.IFS(N18="FG2020US1", "Ibuprofen Tablets (100 MG)", N18="FG0001SEG", "Metformin Tablets (100 MG)", N18="FG0002SEG", "Metformin Tablets (200 MG)", N18="FG0003SEG", "Metformin Tablets (500 MG)", N18="FG00UDI4", "Aspirin Tablets (500 MG)")} -> Metformin Tablets (200 MG) | P18: 4017
A19: 40000002518 | B19: 1010 | C19: 4 | D19: QL040000003118 | E19: =E20-1 -> 45878 | F19: =TIME(RANDBETWEEN(0,10), RANDBETWEEN(0,59), RANDBETWEEN(0,59)) -> 0.17247685 | G19: YA284176 | H19: =E19 -> 45878 | I19: =F19 -> 0.17247685 | J19: =E19 -> 45878 | K19: =I19+TIME(1,RANDBETWEEN(25,50),RANDBETWEEN(0,59)) -> 0.24465278 | L19: Q | M19: 1004528 | N19: FG2020US1 | O19: {=_xlfn.IFS(N19="FG2020US1", "Ibuprofen Tablets (100 MG)", N19="FG0001SEG", "Metformin Tablets (100 MG)", N19="FG0002SEG", "Metformin Tablets (200 MG)", N19="FG0003SEG", "Metformin Tablets (500 MG)", N19="FG00UDI4", "Aspirin Tablets (500 MG)")} -> Ibuprofen Tablets (100 MG) | P19: 4018
A20: 40000002519 | B20: 1010 | C20: 4 | D20: QL040000003119 | E20: =E21 -> 45879 | F20: =TIME(RANDBETWEEN(12,22), RANDBETWEEN(0,59), RANDBETWEEN(0,59)) -> 0.72340278 | G20: TP397880 | H20: =E20 -> 45879 | I20: =F20 -> 0.72340278 | J20: =E20 -> 45879 | K20: =I20+TIME(1,RANDBETWEEN(25,50),RANDBETWEEN(0,59)) -> 0.7871412 | L20: Q | M20: 1004529 | N20: FG00UDI4 | O20: {=_xlfn.IFS(N20="FG2020US1", "Ibuprofen Tablets (100 MG)", N20="FG0001SEG", "Metformin Tablets (100 MG)", N20="FG0002SEG", "Metformin Tablets (200 MG)", N20="FG0003SEG", "Metformin Tablets (500 MG)", N20="FG00UDI4", "Aspirin Tablets (500 MG)")} -> Aspirin Tablets (500 MG) | P20: 4019
A21: 40000002520 | B21: 1010 | C21: 4 | D21: QL040000003120 | E21: =E22-1 -> 45879 | F21: =TIME(RANDBETWEEN(0,10), RANDBETWEEN(0,59), RANDBETWEEN(0,59)) -> 0.37826389 | G21: GC197258 | H21: =E21 -> 45879 | I21: =F21 -> 0.37826389 | J21: =E21 -> 45879 | K21: =I21+TIME(1,RANDBETWEEN(25,50),RANDBETWEEN(0,59)) -> 0.45524306 | L21: Q | M21: 1004530 | N21: FG0001SEG | O21: {=_xlfn.IFS(N21="FG2020US1", "Ibuprofen Tablets (100 MG)", N21="FG0001SEG", "Metformin Tablets (100 MG)", N21="FG0002SEG", "Metformin Tablets (200 MG)", N21="FG0003SEG", "Metformin Tablets (500 MG)", N21="FG00UDI4", "Aspirin Tablets (500 MG)")} -> Metformin Tablets (100 MG) | P21: 4020
A22: 40000002521 | B22: 1010 | C22: 4 | D22: QL040000003121 | E22: =E23 -> 45880 | F22: =TIME(RANDBETWEEN(12,22), RANDBETWEEN(0,59), RANDBETWEEN(0,59)) -> 0.78569444 | G22: ZK384180 | H22: =E22 -> 45880 | I22: =F22 -> 0.78569444 | J22: =E22 -> 45880 | K22: =I22+TIME(1,RANDBETWEEN(25,50),RANDBETWEEN(0,59)) -> 0.85378472 | L22: Q | M22: 1004531 | N22: FG2020US1 | O22: {=_xlfn.IFS(N22="FG2020US1", "Ibuprofen Tablets (100 MG)", N22="FG0001SEG", "Metformin Tablets (100 MG)", N22="FG0002SEG", "Metformin Tablets (200 MG)", N22="FG0003SEG", "Metformin Tablets (500 MG)", N22="FG00UDI4", "Aspirin Tablets (500 MG)")} -> Ibuprofen Tablets (100 MG) | P22: 4021
A23: 40000002522 | B23: 1010 | C23: 4 | D23: QL040000003122 | E23: =E24-1 -> 45880 | F23: =TIME(RANDBETWEEN(0,10), RANDBETWEEN(0,59), RANDBETWEEN(0,59)) -> 0.3933912 | G23: YA284176 | H23: =E23 -> 45880 | I23: =F23 -> 0.3933912 | J23: =E23 -> 45880 | K23: =I23+TIME(1,RANDBETWEEN(25,50),RANDBETWEEN(0,59)) -> 0.46545139 | L23: Q | M23: 1004532 | N23: FG2020US1 | O23: {=_xlfn.IFS(N23="FG2020US1", "Ibuprofen Tablets (100 MG)", N23="FG0001SEG", "Metformin Tablets (100 MG)", N23="FG0002SEG", "Metformin Tablets (200 MG)", N23="FG0003SEG", "Metformin Tablets (500 MG)", N23="FG00UDI4", "Aspirin Tablets (500 MG)")} -> Ibuprofen Tablets (100 MG) | P23: 4022
A24: 40000002523 | B24: 1010 | C24: 4 | D24: QL040000003123 | E24: =E25 -> 45881 | F24: =TIME(RANDBETWEEN(12,22), RANDBETWEEN(0,59), RANDBETWEEN(0,59)) -> 0.54584491 | G24: ZK384180 | H24: =E24 -> 45881 | I24: =F24 -> 0.54584491 | J24: =E24 -> 45881 | K24: =I24+TIME(1,RANDBETWEEN(25,50),RANDBETWEEN(0,59)) -> 0.60946759 | L24: Q | M24: 1004533 | N24: FG0003SEG | O24: {=_xlfn.IFS(N24="FG2020US1", "Ibuprofen Tablets (100 MG)", N24="FG0001SEG", "Metformin Tablets (100 MG)", N24="FG0002SEG", "Metformin Tablets (200 MG)", N24="FG0003SEG", "Metformin Tablets (500 MG)", N24="FG00UDI4", "Aspirin Tablets (500 MG)")} -> Metformin Tablets (500 MG) | P24: 4023
A25: 40000002524 | B25: 1010 | C25: 4 | D25: QL040000003124 | E25: =E26-1 -> 45881 | F25: =TIME(RANDBETWEEN(0,10), RANDBETWEEN(0,59), RANDBETWEEN(0,59)) -> 0.42277778 | G25: GC197258 | H25: =E25 -> 45881 | I25: =F25 -> 0.42277778 | J25: =E25 -> 45881 | K25: =I25+TIME(1,RANDBETWEEN(25,50),RANDBETWEEN(0,59)) -> 0.4874537 | L25: Q | M25: 1004534 | N25: FG0003SEG | O25: {=_xlfn.IFS(N25="FG2020US1", "Ibuprofen Tablets (100 MG)", N25="FG0001SEG", "Metformin Tablets (100 MG)", N25="FG0002SEG", "Metformin Tablets (200 MG)", N25="FG0003SEG", "Metformin Tablets (500 MG)", N25="FG00UDI4", "Aspirin Tablets (500 MG)")} -> Metformin Tablets (500 MG) | P25: 4024
A26: 40000002525 | B26: 1010 | C26: 4 | D26: QL040000003125 | E26: =E27 -> 45882 | F26: =TIME(RANDBETWEEN(12,22), RANDBETWEEN(0,59), RANDBETWEEN(0,59)) -> 0.91469907 | G26: AB406550 | H26: =E26 -> 45882 | I26: =F26 -> 0.91469907 | J26: =E26 -> 45882 | K26: =I26+TIME(1,RANDBETWEEN(25,50),RANDBETWEEN(0,59)) -> 0.98853009 | L26: Q | M26: 1004535 | N26: FG2020US1 | O26: {=_xlfn.IFS(N26="FG2020US1", "Ibuprofen Tablets (100 MG)", N26="FG0001SEG", "Metformin Tablets (100 MG)", N26="FG0002SEG", "Metformin Tablets (200 MG)", N26="FG0003SEG", "Metformin Tablets (500 MG)", N26="FG00UDI4", "Aspirin Tablets (500 MG)")} -> Ibuprofen Tablets (100 MG) | P26: 4025
A27: 40000002526 | B27: 1010 | C27: 4 | D27: QL040000003126 | E27: =E28-1 -> 45882 | F27: =TIME(RANDBETWEEN(0,10), RANDBETWEEN(0,59), RANDBETWEEN(0,59)) -> 0.19553241 | G27: TG509538 | H27: =E27 -> 45882 | I27: =F27 -> 0.19553241 | J27: =E27 -> 45882 | K27: =I27+TIME(1,RANDBETWEEN(25,50),RANDBETWEEN(0,59)) -> 0.27128472 | L27: Q | M27: 1004536 | N27: FG0003SEG | O27: {=_xlfn.IFS(N27="FG2020US1", "Ibuprofen Tablets (100 MG)", N27="FG0001SEG", "Metformin Tablets (100 MG)", N27="FG0002SEG", "Metformin Tablets (200 MG)", N27="FG0003SEG", "Metformin Tablets (500 MG)", N27="FG00UDI4", "Aspirin Tablets (500 MG)")} -> Metformin Tablets (500 MG) | P27: 4026
A28: 40000002527 | B28: 1010 | C28: 4 | D28: QL040000003127 | E28: =E29 -> 45883 | F28: =TIME(RANDBETWEEN(12,22), RANDBETWEEN(0,59), RANDBETWEEN(0,59)) -> 0.77383102 | G28: TP397880 | H28: =E28 -> 45883 | I28: =F28 -> 0.77383102 | J28: =E28 -> 45883 | K28: =I28+TIME(1,RANDBETWEEN(25,50),RANDBETWEEN(0,59)) -> 0.84259259 | L28: Q | M28: 1004537 | N28: FG2020US1 | O28: {=_xlfn.IFS(N28="FG2020US1", "Ibuprofen Tablets (100 MG)", N28="FG0001SEG", "Metformin Tablets (100 MG)", N28="FG0002SEG", "Metformin Tablets (200 MG)", N28="FG0003SEG", "Metformin Tablets (500 MG)", N28="FG00UDI4", "Aspirin Tablets (500 MG)")} -> Ibuprofen Tablets (100 MG) | P28: 4027
A29: 40000002528 | B29: 1010 | C29: 4 | D29: QL040000003128 | E29: =E30-1 -> 45883 | F29: =TIME(RANDBETWEEN(0,10), RANDBETWEEN(0,59), RANDBETWEEN(0,59)) -> 0.25623843 | G29: YA284176 | H29: =E29 -> 45883 | I29: =F29 -> 0.25623843 | J29: =E29 -> 45883 | K29: =I29+TIME(1,RANDBETWEEN(25,50),RANDBETWEEN(0,59)) -> 0.3228125 | L29: Q | M29: 1004538 | N29: FG0001SEG | O29: {=_xlfn.IFS(N29="FG2020US1", "Ibuprofen Tablets (100 MG)", N29="FG0001SEG", "Metformin Tablets (100 MG)", N29="FG0002SEG", "Metformin Tablets (200 MG)", N29="FG0003SEG", "Metformin Tablets (500 MG)", N29="FG00UDI4", "Aspirin Tablets (500 MG)")} -> Metformin Tablets (100 MG) | P29: 4028
A30: 40000002529 | B30: 1010 | C30: 4 | D30: QL040000003129 | E30: =E31 -> 45884 | F30: =TIME(RANDBETWEEN(12,22), RANDBETWEEN(0,59), RANDBETWEEN(0,59)) -> 0.53420139 | G30: AB406550 | H30: =E30 -> 45884 | I30: =F30 -> 0.53420139 | J30: =E30 -> 45884 | K30: =I30+TIME(1,RANDBETWEEN(25,50),RANDBETWEEN(0,59)) -> 0.60662037 | L30: Q | M30: 1004539 | N30: FG0001SEG | O30: {=_xlfn.IFS(N30="FG2020US1", "Ibuprofen Tablets (100 MG)", N30="FG0001SEG", "Metformin Tablets (100 MG)", N30="FG0002SEG", "Metformin Tablets (200 MG)", N30="FG0003SEG", "Metformin Tablets (500 MG)", N30="FG00UDI4", "Aspirin Tablets (500 MG)")} -> Metformin Tablets (100 MG) | P30: 4029
A31: 40000002530 | B31: 1010 | C31: 4 | D31: QL040000003130 | E31: =E32-1 -> 45884 | F31: =TIME(RANDBETWEEN(0,10), RANDBETWEEN(0,59), RANDBETWEEN(0,59)) -> 0.28056713 | G31: GC197258 | H31: =E31 -> 45884 | I31: =F31 -> 0.28056713 | J31: =E31 -> 45884 | K31: =I31+TIME(1,RANDBETWEEN(25,50),RANDBETWEEN(0,59)) -> 0.35686343 | L31: Q | M31: 1004540 | N31: FG00UDI4 | O31: {=_xlfn.IFS(N31="FG2020US1", "Ibuprofen Tablets (100 MG)", N31="FG0001SEG", "Metformin Tablets (100 MG)", N31="FG0002SEG", "Metformin Tablets (200 MG)", N31="FG0003SEG", "Metformin Tablets (500 MG)", N31="FG00UDI4", "Aspirin Tablets (500 MG)")} -> Aspirin Tablets (500 MG) | P31: 4030
A32: 40000002531 | B32: 1010 | C32: 4 | D32: QL040000003131 | E32: =E33 -> 45885 | F32: =TIME(RANDBETWEEN(12,22), RANDBETWEEN(0,59), RANDBETWEEN(0,59)) -> 0.57795139 | G32: TP397880 | H32: =E32 -> 45885 | I32: =F32 -> 0.57795139 | J32: =E32 -> 45885 | K32: =I32+TIME(1,RANDBETWEEN(25,50),RANDBETWEEN(0,59)) -> 0.6502662 | L32: Q | M32: 1004541 | N32: FG0002SEG | O32: {=_xlfn.IFS(N32="FG2020US1", "Ibuprofen Tablets (100 MG)", N32="FG0001SEG", "Metformin Tablets (100 MG)", N32="FG0002SEG", "Metformin Tablets (200 MG)", N32="FG0003SEG", "Metformin Tablets (500 MG)", N32="FG00UDI4", "Aspirin Tablets (500 MG)")} -> Metformin Tablets (200 MG) | P32: 4031
A33: 40000002532 | B33: 1010 | C33: 4 | D33: QL040000003132 | E33: =E34-1 -> 45885 | F33: =TIME(RANDBETWEEN(0,10), RANDBETWEEN(0,59), RANDBETWEEN(0,59)) -> 0.16503472 | G33: GC197258 | H33: =E33 -> 45885 | I33: =F33 -> 0.16503472 | J33: =E33 -> 45885 | K33: =I33+TIME(1,RANDBETWEEN(25,50),RANDBETWEEN(0,59)) -> 0.22746528 | L33: Q | M33: 1004542 | N33: FG0002SEG | O33: {=_xlfn.IFS(N33="FG2020US1", "Ibuprofen Tablets (100 MG)", N33="FG0001SEG", "Metformin Tablets (100 MG)", N33="FG0002SEG", "Metformin Tablets (200 MG)", N33="FG0003SEG", "Metformin Tablets (500 MG)", N33="FG00UDI4", "Aspirin Tablets (500 MG)")} -> Metformin Tablets (200 MG) | P33: 4032
A34: 40000002533 | B34: 1010 | C34: 4 | D34: QL040000003133 | E34: =E35 -> 45886 | F34: =TIME(RANDBETWEEN(12,22), RANDBETWEEN(0,59), RANDBETWEEN(0,59)) -> 0.62068287 | G34: AB406550 | H34: =E34 -> 45886 | I34: =F34 -> 0.62068287 | J34: =E34 -> 45886 | K34: =I34+TIME(1,RANDBETWEEN(25,50),RANDBETWEEN(0,59)) -> 0.68756944 | L34: Q | M34: 1004543 | N34: FG0003SEG | O34: {=_xlfn.IFS(N34="FG2020US1", "Ibuprofen Tablets (100 MG)", N34="FG0001SEG", "Metformin Tablets (100 MG)", N34="FG0002SEG", "Metformin Tablets (200 MG)", N34="FG0003SEG", "Metformin Tablets (500 MG)", N34="FG00UDI4", "Aspirin Tablets (500 MG)")} -> Metformin Tablets (500 MG) | P34: 4033
A35: 40000002534 | B35: 1010 | C35: 4 | D35: QL040000003134 | E35: =E36-1 -> 45886 | F35: =TIME(RANDBETWEEN(0,10), RANDBETWEEN(0,59), RANDBETWEEN(0,59)) -> 0.052638889 | G35: YA284176 | H35: =E35 -> 45886 | I35: =F35 -> 0.052638889 | J35: =E35 -> 45886 | K35: =I35+TIME(1,RANDBETWEEN(25,50),RANDBETWEEN(0,59)) -> 0.12405093 | L35: Q | M35: 1004544 | N35: FG0002SEG | O35: {=_xlfn.IFS(N35="FG2020US1", "Ibuprofen Tablets (100 MG)", N35="FG0001SEG", "Metformin Tablets (100 MG)", N35="FG0002SEG", "Metformin Tablets (200 MG)", N35="FG0003SEG", "Metformin Tablets (500 MG)", N35="FG00UDI4", "Aspirin Tablets (500 MG)")} -> Metformin Tablets (200 MG) | P35: 4034
A36: 40000002535 | B36: 1010 | C36: 4 | D36: QL040000003135 | E36: =E37 -> 45887 | F36: =TIME(RANDBETWEEN(12,22), RANDBETWEEN(0,59), RANDBETWEEN(0,59)) -> 0.85609954 | G36: AB406550 | H36: =E36 -> 45887 | I36: =F36 -> 0.85609954 | J36: =E36 -> 45887 | K36: =I36+TIME(1,RANDBETWEEN(25,50),RANDBETWEEN(0,59)) -> 0.91865741 | L36: Q | M36: 1004545 | N36: FG0001SEG | O36: {=_xlfn.IFS(N36="FG2020US1", "Ibuprofen Tablets (100 MG)", N36="FG0001SEG", "Metformin Tablets (100 MG)", N36="FG0002SEG", "Metformin Tablets (200 MG)", N36="FG0003SEG", "Metformin Tablets (500 MG)", N36="FG00UDI4", "Aspirin Tablets (500 MG)")} -> Metformin Tablets (100 MG) | P36: 4035
A37: 40000002536 | B37: 1010 | C37: 4 | D37: QL040000003136 | E37: =E38-1 -> 45887 | F37: =TIME(RANDBETWEEN(0,10), RANDBETWEEN(0,59), RANDBETWEEN(0,59)) -> 0.22001157 | G37: TG509538 | H37: =E37 -> 45887 | I37: =F37 -> 0.22001157 | J37: =E37 -> 45887 | K37: =I37+TIME(1,RANDBETWEEN(25,50),RANDBETWEEN(0,59)) -> 0.29577546 | L37: Q | M37: 1004546 | N37: FG0003SEG | O37: {=_xlfn.IFS(N37="FG2020US1", "Ibuprofen Tablets (100 MG)", N37="FG0001SEG", "Metformin Tablets (100 MG)", N37="FG0002SEG", "Metformin Tablets (200 MG)", N37="FG0003SEG", "Metformin Tablets (500 MG)", N37="FG00UDI4", "Aspirin Tablets (500 MG)")} -> Metformin Tablets (500 MG) | P37: 4036
A38: 40000002537 | B38: 1010 | C38: 4 | D38: QL040000003137 | E38: =E39 -> 45888 | F38: =TIME(RANDBETWEEN(12,22), RANDBETWEEN(0,59), RANDBETWEEN(0,59)) -> 0.74059028 | G38: TP397880 | H38: =E38 -> 45888 | I38: =F38 -> 0.74059028 | J38: =E38 -> 45888 | K38: =I38+TIME(1,RANDBETWEEN(25,50),RANDBETWEEN(0,59)) -> 0.81429398 | L38: Q | M38: 1004547 | N38: FG2020US1 | O38: {=_xlfn.IFS(N38="FG2020US1", "Ibuprofen Tablets (100 MG)", N38="FG0001SEG", "Metformin Tablets (100 MG)", N38="FG0002SEG", "Metformin Tablets (200 MG)", N38="FG0003SEG", "Metformin Tablets (500 MG)", N38="FG00UDI4", "Aspirin Tablets (500 MG)")} -> Ibuprofen Tablets (100 MG) | P38: 4037
A39: 40000002538 | B39: 1010 | C39: 4 | D39: QL040000003138 | E39: =E40-1 -> 45888 | F39: =TIME(RANDBETWEEN(0,10), RANDBETWEEN(0,59), RANDBETWEEN(0,59)) -> 0.03630787 | G39: GC197258 | H39: =E39 -> 45888 | I39: =F39 -> 0.03630787 | J39: =E39 -> 45888 | K39: =I39+TIME(1,RANDBETWEEN(25,50),RANDBETWEEN(0,59)) -> 0.10803241 | L39: Q | M39: 1004548 | N39: FG00UDI4 | O39: {=_xlfn.IFS(N39="FG2020US1", "Ibuprofen Tablets (100 MG)", N39="FG0001SEG", "Metformin Tablets (100 MG)", N39="FG0002SEG", "Metformin Tablets (200 MG)", N39="FG0003SEG", "Metformin Tablets (500 MG)", N39="FG00UDI4", "Aspirin Tablets (500 MG)")} -> Aspirin Tablets (500 MG) | P39: 4038
A40: 40000002539 | B40: 1010 | C40: 4 | D40: QL040000003139 | E40: =E41 -> 45889 | F40: =TIME(RANDBETWEEN(12,22), RANDBETWEEN(0,59), RANDBETWEEN(0,59)) -> 0.62072917 | G40: ZK384180 | H40: =E40 -> 45889 | I40: =F40 -> 0.62072917 | J40: =E40 -> 45889 | K40: =I40+TIME(1,RANDBETWEEN(25,50),RANDBETWEEN(0,59)) -> 0.68393519 | L40: Q | M40: 1004549 | N40: FG2020US1 | O40: {=_xlfn.IFS(N40="FG2020US1", "Ibuprofen Tablets (100 MG)", N40="FG0001SEG", "Metformin Tablets (100 MG)", N40="FG0002SEG", "Metformin Tablets (200 MG)", N40="FG0003SEG", "Metformin Tablets (500 MG)", N40="FG00UDI4", "Aspirin Tablets (500 MG)")} -> Ibuprofen Tablets (100 MG) | P40: 4039
...

Sheet QAMR - Characteristic Recording
A1: InspectionLot | B1: NodeNo | C1: ProductDescription | D1: CharacteristicCode | E1: CharacteristicDesc | F1: CreatedBy | G1: CreatedOn | H1: Valuation | I1: Inspector | J1: StartDate | K1: StartTime | L1: EndDate | M1: EndTime | N1: Qualitative | O1: Quantative | P1: MinValue | Q1: MaxValue
A2: 40000002501 | B2: 1 | C2: =LOOKUP(A2,'QALS - Inspection Lot Record'!$A$2:$A$361,'QALS - Inspection Lot Record'!$O$2:$O$361) -> Metformin Tablets (100 MG) | D2: 10 | E2: Potency | F2: =LOOKUP(A2,'QALS - Inspection Lot Record'!A:A,'QALS - Inspection Lot Record'!G:G) -> TP397880 | G2: =LOOKUP(A2,'QALS - Inspection Lot Record'!A:A,'QALS - Inspection Lot Record'!E:E) -> 45870 | H2: =IF(AND(P2<=O2,O2<=Q2),"A","R") -> R | I2: =F2 -> TP397880 | J2: =G2 -> 45870 | K2: =LOOKUP(A2,'QALS - Inspection Lot Record'!A:A,'QALS - Inspection Lot Record'!I:I) -> 0.69314815 | L2: =G2 -> 45870 | M2: =K2+TIME(0,RANDBETWEEN(25,50),RANDBETWEEN(0,59)) -> 0.72212963 | O2: 93.5 | P2: 95 | Q2: 102
A3: 40000002501 | B3: 1 | C3: =LOOKUP(A3,'QALS - Inspection Lot Record'!$A$2:$A$361,'QALS - Inspection Lot Record'!$O$2:$O$361) -> Metformin Tablets (100 MG) | D3: 20 | E3: PH Level | F3: =LOOKUP(A3,'QALS - Inspection Lot Record'!A:A,'QALS - Inspection Lot Record'!G:G) -> TP397880 | G3: =LOOKUP(A3,'QALS - Inspection Lot Record'!A:A,'QALS - Inspection Lot Record'!E:E) -> 45870 | H3: =IF(AND(P3<=O3,O3<=Q3),"A","R") -> R | I3: =F3 -> TP397880 | J3: =G3 -> 45870 | K3: =LOOKUP(A3,'QALS - Inspection Lot Record'!A:A,'QALS - Inspection Lot Record'!I:I) -> 0.69314815 | L3: =G3 -> 45870 | M3: =K3+TIME(0,RANDBETWEEN(25,50),RANDBETWEEN(0,59)) -> 0.72787037 | O3: 1.7 | P3: 3.5 | Q3: 11
A4: 40000002501 | B4: 1 | C4: =LOOKUP(A4,'QALS - Inspection Lot Record'!$A$2:$A$361,'QALS - Inspection Lot Record'!$O$2:$O$361) -> Metformin Tablets (100 MG) | D4: 30 | E4: Appearance | F4: =LOOKUP(A4,'QALS - Inspection Lot Record'!A:A,'QALS - Inspection Lot Record'!G:G) -> TP397880 | G4: =LOOKUP(A4,'QALS - Inspection Lot Record'!A:A,'QALS - Inspection Lot Record'!E:E) -> 45870 | H4: =IF(AND(P4<=O4,O4<=Q4),"A","R") -> A | I4: =F4 -> TP397880 | J4: =G4 -> 45870 | K4: =LOOKUP(A4,'QALS - Inspection Lot Record'!A:A,'QALS - Inspection Lot Record'!I:I) -> 0.69314815 | L4: =G4 -> 45870 | M4: =K4+TIME(0,RANDBETWEEN(25,50),RANDBETWEEN(0,59)) -> 0.71266204 | N4: Complies
A5: 40000002501 | B5: 1 | C5: =LOOKUP(A5,'QALS - Inspection Lot Record'!$A$2:$A$361,'QALS - Inspection Lot Record'!$O$2:$O$361) -> Metformin Tablets (100 MG) | D5: 40 | E5: Impurities | F5: =LOOKUP(A5,'QALS - Inspection Lot Record'!A:A,'QALS - Inspection Lot Record'!G:G) -> TP397880 | G5: =LOOKUP(A5,'QALS - Inspection Lot Record'!A:A,'QALS - Inspection Lot Record'!E:E) -> 45870 | H5: =IF(AND(P5<=O5,O5<=Q5),"A","R") -> A | I5: =F5 -> TP397880 | J5: =G5 -> 45870 | K5: =LOOKUP(A5,'QALS - Inspection Lot Record'!A:A,'QALS - Inspection Lot Record'!I:I) -> 0.69314815 | L5: =G5 -> 45870 | M5: =K5+TIME(0,RANDBETWEEN(25,50),RANDBETWEEN(0,59)) -> 0.72487269 | O5: 0 | P5: 0 | Q5: 1
A6: 40000002501 | B6: 1 | C6: =LOOKUP(A6,'QALS - Inspection Lot Record'!$A$2:$A$361,'QALS - Inspection Lot Record'!$O$2:$O$361) -> Metformin Tablets (100 MG) | D6: 50 | E6: Dissolution Rate - 15 Mins | F6: =LOOKUP(A6,'QALS - Inspection Lot Record'!A:A,'QALS - Inspection Lot Record'!G:G) -> TP397880 | G6: =LOOKUP(A6,'QALS - Inspection Lot Record'!A:A,'QALS - Inspection Lot Record'!E:E) -> 45870 | H6: =IF(AND(P6<=O6,O6<=Q6),"A","R") -> A | I6: =F6 -> TP397880 | J6: =G6 -> 45870 | K6: =LOOKUP(A6,'QALS - Inspection Lot Record'!A:A,'QALS - Inspection Lot Record'!I:I) -> 0.69314815 | L6: =G6 -> 45870 | M6: =K6+TIME(0,RANDBETWEEN(25,50),RANDBETWEEN(0,59)) -> 0.71646991 | O6: 50 | P6: 40 | Q6: 60
A7: 40000002501 | B7: 1 | C7: =LOOKUP(A7,'QALS - Inspection Lot Record'!$A$2:$A$361,'QALS - Inspection Lot Record'!$O$2:$O$361) -> Metformin Tablets (100 MG) | D7: 60 | E7: Dissolution Rate - 30 Mins | F7: =LOOKUP(A7,'QALS - Inspection Lot Record'!A:A,'QALS - Inspection Lot Record'!G:G) -> TP397880 | G7: =LOOKUP(A7,'QALS - Inspection Lot Record'!A:A,'QALS - Inspection Lot Record'!E:E) -> 45870 | H7: =IF(AND(P7<=O7,O7<=Q7),"A","R") -> A | I7: =F7 -> TP397880 | J7: =G7 -> 45870 | K7: =LOOKUP(A7,'QALS - Inspection Lot Record'!A:A,'QALS - Inspection Lot Record'!I:I) -> 0.69314815 | L7: =G7 -> 45870 | M7: =K7+TIME(0,RANDBETWEEN(25,50),RANDBETWEEN(0,59)) -> 0.72085648 | O7: 77.5 | P7: 70 | Q7: 85
A8: 40000002501 | B8: 1 | C8: =LOOKUP(A8,'QALS - Inspection Lot Record'!$A$2:$A$361,'QALS - Inspection Lot Record'!$O$2:$O$361) -> Metformin Tablets (100 MG) | D8: 70 | E8: Dissolution Rate - 40 Mins | F8: =LOOKUP(A8,'QALS - Inspection Lot Record'!A:A,'QALS - Inspection Lot Record'!G:G) -> TP397880 | G8: =LOOKUP(A8,'QALS - Inspection Lot Record'!A:A,'QALS - Inspection Lot Record'!E:E) -> 45870 | H8: =IF(AND(P8<=O8,O8<=Q8),"A","R") -> A | I8: =F8 -> TP397880 | J8: =G8 -> 45870 | K8: =LOOKUP(A8,'QALS - Inspection Lot Record'!A:A,'QALS - Inspection Lot Record'!I:I) -> 0.69314815 | L8: =G8 -> 45870 | M8: =K8+TIME(0,RANDBETWEEN(25,50),RANDBETWEEN(0,59)) -> 0.72561343 | O8: 85 | P8: 80 | Q8: 90
A9: 40000002501 | B9: 1 | C9: =LOOKUP(A9,'QALS - Inspection Lot Record'!$A$2:$A$361,'QALS - Inspection Lot Record'!$O$2:$O$361) -> Metformin Tablets (100 MG) | D9: 80 | E9: Process Temp | F9: =LOOKUP(A9,'QALS - Inspection Lot Record'!A:A,'QALS - Inspection Lot Record'!G:G) -> TP397880 | G9: =LOOKUP(A9,'QALS - Inspection Lot Record'!A:A,'QALS - Inspection Lot Record'!E:E) -> 45870 | H9: =IF(AND(P9<=O9,O9<=Q9),"A","R") -> A | I9: =F9 -> TP397880 | J9: =G9 -> 45870 | K9: =LOOKUP(A9,'QALS - Inspection Lot Record'!A:A,'QALS - Inspection Lot Record'!I:I) -> 0.69314815 | L9: =G9 -> 45870 | M9: =K9+TIME(0,RANDBETWEEN(25,50),RANDBETWEEN(0,59)) -> 0.7149537 | O9: 24 | P9: 23 | Q9: 25
A10: 40000002502 | B10: 1 | C10: =LOOKUP(A10,'QALS - Inspection Lot Record'!$A$2:$A$361,'QALS - Inspection Lot Record'!$O$2:$O$361) -> Ibuprofen Tablets (100 MG) | D10: 10 | E10: Potency | F10: =LOOKUP(A10,'QALS - Inspection Lot Record'!A:A,'QALS - Inspection Lot Record'!G:G) -> YA284176 | G10: =LOOKUP(A10,'QALS - Inspection Lot Record'!A:A,'QALS - Inspection Lot Record'!E:E) -> 45870 | H10: =IF(AND(P10<=O10,O10<=Q10),"A","R") -> R | I10: =F10 -> YA284176 | J10: =G10 -> 45870 | K10: =LOOKUP(A10,'QALS - Inspection Lot Record'!A:A,'QALS - Inspection Lot Record'!I:I) -> 0.098055556 | L10: =G10 -> 45870 | M10: =K10+TIME(0,RANDBETWEEN(25,50),RANDBETWEEN(0,59)) -> 0.12420139 | O10: 94 | P10: 95 | Q10: 102
A11: 40000002502 | B11: 1 | C11: =LOOKUP(A11,'QALS - Inspection Lot Record'!$A$2:$A$361,'QALS - Inspection Lot Record'!$O$2:$O$361) -> Ibuprofen Tablets (100 MG) | D11: 20 | E11: PH Level | F11: =LOOKUP(A11,'QALS - Inspection Lot Record'!A:A,'QALS - Inspection Lot Record'!G:G) -> YA284176 | G11: =LOOKUP(A11,'QALS - Inspection Lot Record'!A:A,'QALS - Inspection Lot Record'!E:E) -> 45870 | H11: =IF(AND(P11<=O11,O11<=Q11),"A","R") -> A | I11: =F11 -> YA284176 | J11: =G11 -> 45870 | K11: =LOOKUP(A11,'QALS - Inspection Lot Record'!A:A,'QALS - Inspection Lot Record'!I:I) -> 0.098055556 | L11: =G11 -> 45870 | M11: =K11+TIME(0,RANDBETWEEN(25,50),RANDBETWEEN(0,59)) -> 0.12679398 | O11: 7.25 | P11: 3.5 | Q11: 11
A12: 40000002502 | B12: 1 | C12: =LOOKUP(A12,'QALS - Inspection Lot Record'!$A$2:$A$361,'QALS - Inspection Lot Record'!$O$2:$O$361) -> Ibuprofen Tablets (100 MG) | D12: 30 | E12: Appearance | F12: =LOOKUP(A12,'QALS - Inspection Lot Record'!A:A,'QALS - Inspection Lot Record'!G:G) -> YA284176 | G12: =LOOKUP(A12,'QALS - Inspection Lot Record'!A:A,'QALS - Inspection Lot Record'!E:E) -> 45870 | H12: =IF(AND(P12<=O12,O12<=Q12),"A","R") -> A | I12: =F12 -> YA284176 | J12: =G12 -> 45870 | K12: =LOOKUP(A12,'QALS - Inspection Lot Record'!A:A,'QALS - Inspection Lot Record'!I:I) -> 0.098055556 | L12: =G12 -> 45870 | M12: =K12+TIME(0,RANDBETWEEN(25,50),RANDBETWEEN(0,59)) -> 0.13340278 | N12: Complies
A13: 40000002502 | B13: 1 | C13: =LOOKUP(A13,'QALS - Inspection Lot Record'!$A$2:$A$361,'QALS - Inspection Lot Record'!$O$2:$O$361) -> Ibuprofen Tablets (100 MG) | D13: 40 | E13: Impurities | F13: =LOOKUP(A13,'QALS - Inspection Lot Record'!A:A,'QALS - Inspection Lot Record'!G:G) -> YA284176 | G13: =LOOKUP(A13,'QALS - Inspection Lot Record'!A:A,'QALS - Inspection Lot Record'!E:E) -> 45870 | H13: =IF(AND(P13<=O13,O13<=Q13),"A","R") -> A | I13: =F13 -> YA284176 | J13: =G13 -> 45870 | K13: =LOOKUP(A13,'QALS - Inspection Lot Record'!A:A,'QALS - Inspection Lot Record'!I:I) -> 0.098055556 | L13: =G13 -> 45870 | M13: =K13+TIME(0,RANDBETWEEN(25,50),RANDBETWEEN(0,59)) -> 0.12561343 | O13: 0 | P13: 0 | Q13: 1
A14: 40000002502 | B14: 1 | C14: =LOOKUP(A14,'QALS - Inspection Lot Record'!$A$2:$A$361,'QALS - Inspection Lot Record'!$O$2:$O$361) -> Ibuprofen Tablets (100 MG) | D14: 50 | E14: Dissolution Rate - 15 Mins | F14: =LOOKUP(A14,'QALS - Inspection Lot Record'!A:A,'QALS - Inspection Lot Record'!G:G) -> YA284176 | G14: =LOOKUP(A14,'QALS - Inspection Lot Record'!A:A,'QALS - Inspection Lot Record'!E:E) -> 45870 | H14: =IF(AND(P14<=O14,O14<=Q14),"A","R") -> A | I14: =F14 -> YA284176 | J14: =G14 -> 45870 | K14: =LOOKUP(A14,'QALS - Inspection Lot Record'!A:A,'QALS - Inspection Lot Record'!I:I) -> 0.098055556 | L14: =G14 -> 45870 | M14: =K14+TIME(0,RANDBETWEEN(25,50),RANDBETWEEN(0,59)) -> 0.12502315 | O14: 50 | P14: 40 | Q14: 60
A15: 40000002502 | B15: 1 | C15: =LOOKUP(A15,'QALS - Inspection Lot Record'!$A$2:$A$361,'QALS - Inspection Lot Record'!$O$2:$O$361) -> Ibuprofen Tablets (100 MG) | D15: 60 | E15: Dissolution Rate - 30 Mins | F15: =LOOKUP(A15,'QALS - Inspection Lot Record'!A:A,'QALS - Inspection Lot Record'!G:G) -> YA284176 | G15: =LOOKUP(A15,'QALS - Inspection Lot Record'!A:A,'QALS - Inspection Lot Record'!E:E) -> 45870 | H15: =IF(AND(P15<=O15,O15<=Q15),"A","R") -> A | I15: =F15 -> YA284176 | J15: =G15 -> 45870 | K15: =LOOKUP(A15,'QALS - Inspection Lot Record'!A:A,'QALS - Inspection Lot Record'!I:I) -> 0.098055556 | L15: =G15 -> 45870 | M15: =K15+TIME(0,RANDBETWEEN(25,50),RANDBETWEEN(0,59)) -> 0.12506944 | O15: 77.5 | P15: 70 | Q15: 85
A16: 40000002502 | B16: 1 | C16: =LOOKUP(A16,'QALS - Inspection Lot Record'!$A$2:$A$361,'QALS - Inspection Lot Record'!$O$2:$O$361) -> Ibuprofen Tablets (100 MG) | D16: 70 | E16: Dissolution Rate - 40 Mins | F16: =LOOKUP(A16,'QALS - Inspection Lot Record'!A:A,'QALS - Inspection Lot Record'!G:G) -> YA284176 | G16: =LOOKUP(A16,'QALS - Inspection Lot Record'!A:A,'QALS - Inspection Lot Record'!E:E) -> 45870 | H16: =IF(AND(P16<=O16,O16<=Q16),"A","R") -> A | I16: =F16 -> YA284176 | J16: =G16 -> 45870 | K16: =LOOKUP(A16,'QALS - Inspection Lot Record'!A:A,'QALS - Inspection Lot Record'!I:I) -> 0.098055556 | L16: =G16 -> 45870 | M16: =K16+TIME(0,RANDBETWEEN(25,50),RANDBETWEEN(0,59)) -> 0.11913194 | O16: 85 | P16: 80 | Q16: 90
A17: 40000002502 | B17: 1 | C17: =LOOKUP(A17,'QALS - Inspection Lot Record'!$A$2:$A$361,'QALS - Inspection Lot Record'!$O$2:$O$361) -> Ibuprofen Tablets (100 MG) | D17: 80 | E17: Process Temp | F17: =LOOKUP(A17,'QALS - Inspection Lot Record'!A:A,'QALS - Inspection Lot Record'!G:G) -> YA284176 | G17: =LOOKUP(A17,'QALS - Inspection Lot Record'!A:A,'QALS - Inspection Lot Record'!E:E) -> 45870 | H17: =IF(AND(P17<=O17,O17<=Q17),"A","R") -> A | I17: =F17 -> YA284176 | J17: =G17 -> 45870 | K17: =LOOKUP(A17,'QALS - Inspection Lot Record'!A:A,'QALS - Inspection Lot Record'!I:I) -> 0.098055556 | L17: =G17 -> 45870 | M17: =K17+TIME(0,RANDBETWEEN(25,50),RANDBETWEEN(0,59)) -> 0.12862269 | O17: 24 | P17: 23 | Q17: 25
A18: 40000002503 | B18: 1 | C18: =LOOKUP(A18,'QALS - Inspection Lot Record'!$A$2:$A$361,'QALS - Inspection Lot Record'!$O$2:$O$361) -> Metformin Tablets (100 MG) | D18: 10 | E18: Potency | F18: =LOOKUP(A18,'QALS - Inspection Lot Record'!A:A,'QALS - Inspection Lot Record'!G:G) -> ZK384180 | G18: =LOOKUP(A18,'QALS - Inspection Lot Record'!A:A,'QALS - Inspection Lot Record'!E:E) -> 45871 | H18: =IF(AND(P18<=O18,O18<=Q18),"A","R") -> A | I18: =F18 -> ZK384180 | J18: =G18 -> 45871 | K18: =LOOKUP(A18,'QALS - Inspection Lot Record'!A:A,'QALS - Inspection Lot Record'!I:I) -> 0.90376157 | L18: =G18 -> 45871 | M18: =K18+TIME(0,RANDBETWEEN(25,50),RANDBETWEEN(0,59)) -> 0.93170139 | O18: 98.4 | P18: 95 | Q18: 102
A19: 40000002503 | B19: 1 | C19: =LOOKUP(A19,'QALS - Inspection Lot Record'!$A$2:$A$361,'QALS - Inspection Lot Record'!$O$2:$O$361) -> Metformin Tablets (100 MG) | D19: 20 | E19: PH Level | F19: =LOOKUP(A19,'QALS - Inspection Lot Record'!A:A,'QALS - Inspection Lot Record'!G:G) -> ZK384180 | G19: =LOOKUP(A19,'QALS - Inspection Lot Record'!A:A,'QALS - Inspection Lot Record'!E:E) -> 45871 | H19: =IF(AND(P19<=O19,O19<=Q19),"A","R") -> A | I19: =F19 -> ZK384180 | J19: =G19 -> 45871 | K19: =LOOKUP(A19,'QALS - Inspection Lot Record'!A:A,'QALS - Inspection Lot Record'!I:I) -> 0.90376157 | L19: =G19 -> 45871 | M19: =K19+TIME(0,RANDBETWEEN(25,50),RANDBETWEEN(0,59)) -> 0.92895833 | O19: 3.9 | P19: 3.5 | Q19: 11
A20: 40000002503 | B20: 1 | C20: =LOOKUP(A20,'QALS - Inspection Lot Record'!$A$2:$A$361,'QALS - Inspection Lot Record'!$O$2:$O$361) -> Metformin Tablets (100 MG) | D20: 30 | E20: Appearance | F20: =LOOKUP(A20,'QALS - Inspection Lot Record'!A:A,'QALS - Inspection Lot Record'!G:G) -> ZK384180 | G20: =LOOKUP(A20,'QALS - Inspection Lot Record'!A:A,'QALS - Inspection Lot Record'!E:E) -> 45871 | H20: =IF(AND(P20<=O20,O20<=Q20),"A","R") -> A | I20: =F20 -> ZK384180 | J20: =G20 -> 45871 | K20: =LOOKUP(A20,'QALS - Inspection Lot Record'!A:A,'QALS - Inspection Lot Record'!I:I) -> 0.90376157 | L20: =G20 -> 45871 | M20: =K20+TIME(0,RANDBETWEEN(25,50),RANDBETWEEN(0,59)) -> 0.92446759 | N20: Complies
A21: 40000002503 | B21: 1 | C21: =LOOKUP(A21,'QALS - Inspection Lot Record'!$A$2:$A$361,'QALS - Inspection Lot Record'!$O$2:$O$361) -> Metformin Tablets (100 MG) | D21: 40 | E21: Impurities | F21: =LOOKUP(A21,'QALS - Inspection Lot Record'!A:A,'QALS - Inspection Lot Record'!G:G) -> ZK384180 | G21: =LOOKUP(A21,'QALS - Inspection Lot Record'!A:A,'QALS - Inspection Lot Record'!E:E) -> 45871 | H21: =IF(AND(P21<=O21,O21<=Q21),"A","R") -> R | I21: =F21 -> ZK384180 | J21: =G21 -> 45871 | K21: =LOOKUP(A21,'QALS - Inspection Lot Record'!A:A,'QALS - Inspection Lot Record'!I:I) -> 0.90376157 | L21: =G21 -> 45871 | M21: =K21+TIME(0,RANDBETWEEN(25,50),RANDBETWEEN(0,59)) -> 0.92174769 | O21: 1.2 | P21: 0 | Q21: 1
A22: 40000002503 | B22: 1 | C22: =LOOKUP(A22,'QALS - Inspection Lot Record'!$A$2:$A$361,'QALS - Inspection Lot Record'!$O$2:$O$361) -> Metformin Tablets (100 MG) | D22: 50 | E22: Dissolution Rate - 15 Mins | F22: =LOOKUP(A22,'QALS - Inspection Lot Record'!A:A,'QALS - Inspection Lot Record'!G:G) -> ZK384180 | G22: =LOOKUP(A22,'QALS - Inspection Lot Record'!A:A,'QALS - Inspection Lot Record'!E:E) -> 45871 | H22: =IF(AND(P22<=O22,O22<=Q22),"A","R") -> R | I22: =F22 -> ZK384180 | J22: =G22 -> 45871 | K22: =LOOKUP(A22,'QALS - Inspection Lot Record'!A:A,'QALS - Inspection Lot Record'!I:I) -> 0.90376157 | L22: =G22 -> 45871 | M22: =K22+TIME(0,RANDBETWEEN(25,50),RANDBETWEEN(0,59)) -> 0.93175926 | O22: 38.7 | P22: 40 | Q22: 60
A23: 40000002503 | B23: 1 | C23: =LOOKUP(A23,'QALS - Inspection Lot Record'!$A$2:$A$361,'QALS - Inspection Lot Record'!$O$2:$O$361) -> Metformin Tablets (100 MG) | D23: 60 | E23: Dissolution Rate - 30 Mins | F23: =LOOKUP(A23,'QALS - Inspection Lot Record'!A:A,'QALS - Inspection Lot Record'!G:G) -> ZK384180 | G23: =LOOKUP(A23,'QALS - Inspection Lot Record'!A:A,'QALS - Inspection Lot Record'!E:E) -> 45871 | H23: =IF(AND(P23<=O23,O23<=Q23),"A","R") -> R | I23: =F23 -> ZK384180 | J23: =G23 -> 45871 | K23: =LOOKUP(A23,'QALS - Inspection Lot Record'!A:A,'QALS - Inspection Lot Record'!I:I) -> 0.90376157 | L23: =G23 -> 45871 | M23: =K23+TIME(0,RANDBETWEEN(25,50),RANDBETWEEN(0,59)) -> 0.93677083 | O23: 68 | P23: 70 | Q23: 85
A24: 40000002503 | B24: 1 | C24: =LOOKUP(A24,'QALS - Inspection Lot Record'!$A$2:$A$361,'QALS - Inspection Lot Record'!$O$2:$O$361) -> Metformin Tablets (100 MG) | D24: 70 | E24: Dissolution Rate - 40 Mins | F24: =LOOKUP(A24,'QALS - Inspection Lot Record'!A:A,'QALS - Inspection Lot Record'!G:G) -> ZK384180 | G24: =LOOKUP(A24,'QALS - Inspection Lot Record'!A:A,'QALS - Inspection Lot Record'!E:E) -> 45871 | H24: =IF(AND(P24<=O24,O24<=Q24),"A","R") -> A | I24: =F24 -> ZK384180 | J24: =G24 -> 45871 | K24: =LOOKUP(A24,'QALS - Inspection Lot Record'!A:A,'QALS - Inspection Lot Record'!I:I) -> 0.90376157 | L24: =G24 -> 45871 | M24: =K24+TIME(0,RANDBETWEEN(25,50),RANDBETWEEN(0,59)) -> 0.9309375 | O24: 84.3 | P24: 80 | Q24: 90
A25: 40000002503 | B25: 1 | C25: =LOOKUP(A25,'QALS - Inspection Lot Record'!$A$2:$A$361,'QALS - Inspection Lot Record'!$O$2:$O$361) -> Metformin Tablets (100 MG) | D25: 80 | E25: Process Temp | F25: =LOOKUP(A25,'QALS - Inspection Lot Record'!A:A,'QALS - Inspection Lot Record'!G:G) -> ZK384180 | G25: =LOOKUP(A25,'QALS - Inspection Lot Record'!A:A,'QALS - Inspection Lot Record'!E:E) -> 45871 | H25: =IF(AND(P25<=O25,O25<=Q25),"A","R") -> A | I25: =F25 -> ZK384180 | J25: =G25 -> 45871 | K25: =LOOKUP(A25,'QALS - Inspection Lot Record'!A:A,'QALS - Inspection Lot Record'!I:I) -> 0.90376157 | L25: =G25 -> 45871 | M25: =K25+TIME(0,RANDBETWEEN(25,50),RANDBETWEEN(0,59)) -> 0.92445602 | O25: 23.5 | P25: 23 | Q25: 25
A26: 40000002504 | B26: 1 | C26: =LOOKUP(A26,'QALS - Inspection Lot Record'!$A$2:$A$361,'QALS - Inspection Lot Record'!$O$2:$O$361) -> Metformin Tablets (100 MG) | D26: 10 | E26: Potency | F26: =LOOKUP(A26,'QALS - Inspection Lot Record'!A:A,'QALS - Inspection Lot Record'!G:G) -> YA284176 | G26: =LOOKUP(A26,'QALS - Inspection Lot Record'!A:A,'QALS - Inspection Lot Record'!E:E) -> 45871 | H26: =IF(AND(P26<=O26,O26<=Q26),"A","R") -> R | I26: =F26 -> YA284176 | J26: =G26 -> 45871 | K26: =LOOKUP(A26,'QALS - Inspection Lot Record'!A:A,'QALS - Inspection Lot Record'!I:I) -> 0.098969907 | L26: =G26 -> 45871 | M26: =K26+TIME(0,RANDBETWEEN(25,50),RANDBETWEEN(0,59)) -> 0.1328588 | O26: 93.6 | P26: 95 | Q26: 102
A27: 40000002504 | B27: 1 | C27: =LOOKUP(A27,'QALS - Inspection Lot Record'!$A$2:$A$361,'QALS - Inspection Lot Record'!$O$2:$O$361) -> Metformin Tablets (100 MG) | D27: 20 | E27: PH Level | F27: =LOOKUP(A27,'QALS - Inspection Lot Record'!A:A,'QALS - Inspection Lot Record'!G:G) -> YA284176 | G27: =LOOKUP(A27,'QALS - Inspection Lot Record'!A:A,'QALS - Inspection Lot Record'!E:E) -> 45871 | H27: =IF(AND(P27<=O27,O27<=Q27),"A","R") -> R | I27: =F27 -> YA284176 | J27: =G27 -> 45871 | K27: =LOOKUP(A27,'QALS - Inspection Lot Record'!A:A,'QALS - Inspection Lot Record'!I:I) -> 0.098969907 | L27: =G27 -> 45871 | M27: =K27+TIME(0,RANDBETWEEN(25,50),RANDBETWEEN(0,59)) -> 0.13256944 | O27: 1.8 | P27: 3.5 | Q27: 11
A28: 40000002504 | B28: 1 | C28: =LOOKUP(A28,'QALS - Inspection Lot Record'!$A$2:$A$361,'QALS - Inspection Lot Record'!$O$2:$O$361) -> Metformin Tablets (100 MG) | D28: 30 | E28: Appearance | F28: =LOOKUP(A28,'QALS - Inspection Lot Record'!A:A,'QALS - Inspection Lot Record'!G:G) -> YA284176 | G28: =LOOKUP(A28,'QALS - Inspection Lot Record'!A:A,'QALS - Inspection Lot Record'!E:E) -> 45871 | H28: =IF(AND(P28<=O28,O28<=Q28),"A","R") -> A | I28: =F28 -> YA284176 | J28: =G28 -> 45871 | K28: =LOOKUP(A28,'QALS - Inspection Lot Record'!A:A,'QALS - Inspection Lot Record'!I:I) -> 0.098969907 | L28: =G28 -> 45871 | M28: =K28+TIME(0,RANDBETWEEN(25,50),RANDBETWEEN(0,59)) -> 0.13085648 | N28: Complies
A29: 40000002504 | B29: 1 | C29: =LOOKUP(A29,'QALS - Inspection Lot Record'!$A$2:$A$361,'QALS - Inspection Lot Record'!$O$2:$O$361) -> Metformin Tablets (100 MG) | D29: 40 | E29: Impurities | F29: =LOOKUP(A29,'QALS - Inspection Lot Record'!A:A,'QALS - Inspection Lot Record'!G:G) -> YA284176 | G29: =LOOKUP(A29,'QALS - Inspection Lot Record'!A:A,'QALS - Inspection Lot Record'!E:E) -> 45871 | H29: =IF(AND(P29<=O29,O29<=Q29),"A","R") -> A | I29: =F29 -> YA284176 | J29: =G29 -> 45871 | K29: =LOOKUP(A29,'QALS - Inspection Lot Record'!A:A,'QALS - Inspection Lot Record'!I:I) -> 0.098969907 | L29: =G29 -> 45871 | M29: =K29+TIME(0,RANDBETWEEN(25,50),RANDBETWEEN(0,59)) -> 0.13396991 | O29: 0.5 | P29: 0 | Q29: 1
A30: 40000002504 | B30: 1 | C30: =LOOKUP(A30,'QALS - Inspection Lot Record'!$A$2:$A$361,'QALS - Inspection Lot Record'!$O$2:$O$361) -> Metformin Tablets (100 MG) | D30: 50 | E30: Dissolution Rate - 15 Mins | F30: =LOOKUP(A30,'QALS - Inspection Lot Record'!A:A,'QALS - Inspection Lot Record'!G:G) -> YA284176 | G30: =LOOKUP(A30,'QALS - Inspection Lot Record'!A:A,'QALS - Inspection Lot Record'!E:E) -> 45871 | H30: =IF(AND(P30<=O30,O30<=Q30),"A","R") -> R | I30: =F30 -> YA284176 | J30: =G30 -> 45871 | K30: =LOOKUP(A30,'QALS - Inspection Lot Record'!A:A,'QALS - Inspection Lot Record'!I:I) -> 0.098969907 | L30: =G30 -> 45871 | M30: =K30+TIME(0,RANDBETWEEN(25,50),RANDBETWEEN(0,59)) -> 0.13261574 | O30: 38.2 | P30: 40 | Q30: 60
A31: 40000002504 | B31: 1 | C31: =LOOKUP(A31,'QALS - Inspection Lot Record'!$A$2:$A$361,'QALS - Inspection Lot Record'!$O$2:$O$361) -> Metformin Tablets (100 MG) | D31: 60 | E31: Dissolution Rate - 30 Mins | F31: =LOOKUP(A31,'QALS - Inspection Lot Record'!A:A,'QALS - Inspection Lot Record'!G:G) -> YA284176 | G31: =LOOKUP(A31,'QALS - Inspection Lot Record'!A:A,'QALS - Inspection Lot Record'!E:E) -> 45871 | H31: =IF(AND(P31<=O31,O31<=Q31),"A","R") -> A | I31: =F31 -> YA284176 | J31: =G31 -> 45871 | K31: =LOOKUP(A31,'QALS - Inspection Lot Record'!A:A,'QALS - Inspection Lot Record'!I:I) -> 0.098969907 | L31: =G31 -> 45871 | M31: =K31+TIME(0,RANDBETWEEN(25,50),RANDBETWEEN(0,59)) -> 0.12650463 | O31: 74.3 | P31: 70 | Q31: 85
A32: 40000002504 | B32: 1 | C32: =LOOKUP(A32,'QALS - Inspection Lot Record'!$A$2:$A$361,'QALS - Inspection Lot Record'!$O$2:$O$361) -> Metformin Tablets (100 MG) | D32: 70 | E32: Dissolution Rate - 40 Mins | F32: =LOOKUP(A32,'QALS - Inspection Lot Record'!A:A,'QALS - Inspection Lot Record'!G:G) -> YA284176 | G32: =LOOKUP(A32,'QALS - Inspection Lot Record'!A:A,'QALS - Inspection Lot Record'!E:E) -> 45871 | H32: =IF(AND(P32<=O32,O32<=Q32),"A","R") -> A | I32: =F32 -> YA284176 | J32: =G32 -> 45871 | K32: =LOOKUP(A32,'QALS - Inspection Lot Record'!A:A,'QALS - Inspection Lot Record'!I:I) -> 0.098969907 | L32: =G32 -> 45871 | M32: =K32+TIME(0,RANDBETWEEN(25,50),RANDBETWEEN(0,59)) -> 0.13020833 | O32: 86.5 | P32: 80 | Q32: 90
A33: 40000002504 | B33: 1 | C33: =LOOKUP(A33,'QALS - Inspection Lot Record'!$A$2:$A$361,'QALS - Inspection Lot Record'!$O$2:$O$361) -> Metformin Tablets (100 MG) | D33: 80 | E33: Process Temp | F33: =LOOKUP(A33,'QALS - Inspection Lot Record'!A:A,'QALS - Inspection Lot Record'!G:G) -> YA284176 | G33: =LOOKUP(A33,'QALS - Inspection Lot Record'!A:A,'QALS - Inspection Lot Record'!E:E) -> 45871 | H33: =IF(AND(P33<=O33,O33<=Q33),"A","R") -> A | I33: =F33 -> YA284176 | J33: =G33 -> 45871 | K33: =LOOKUP(A33,'QALS - Inspection Lot Record'!A:A,'QALS - Inspection Lot Record'!I:I) -> 0.098969907 | L33: =G33 -> 45871 | M33: =K33+TIME(0,RANDBETWEEN(25,50),RANDBETWEEN(0,59)) -> 0.116875 | O33: 24 | P33: 23 | Q33: 25
A34: 40000002505 | B34: 1 | C34: =LOOKUP(A34,'QALS - Inspection Lot Record'!$A$2:$A$361,'QALS - Inspection Lot Record'!$O$2:$O$361) -> Metformin Tablets (500 MG) | D34: 10 | E34: Potency | F34: =LOOKUP(A34,'QALS - Inspection Lot Record'!A:A,'QALS - Inspection Lot Record'!G:G) -> TP397880 | G34: =LOOKUP(A34,'QALS - Inspection Lot Record'!A:A,'QALS - Inspection Lot Record'!E:E) -> 45872 | H34: =IF(AND(P34<=O34,O34<=Q34),"A","R") -> R | I34: =F34 -> TP397880 | J34: =G34 -> 45872 | K34: =LOOKUP(A34,'QALS - Inspection Lot Record'!A:A,'QALS - Inspection Lot Record'!I:I) -> 0.54824074 | L34: =G34 -> 45872 | M34: =K34+TIME(0,RANDBETWEEN(25,50),RANDBETWEEN(0,59)) -> 0.58125 | O34: 93.9 | P34: 95 | Q34: 105
A35: 40000002505 | B35: 1 | C35: =LOOKUP(A35,'QALS - Inspection Lot Record'!$A$2:$A$361,'QALS - Inspection Lot Record'!$O$2:$O$361) -> Metformin Tablets (500 MG) | D35: 20 | E35: PH Level | F35: =LOOKUP(A35,'QALS - Inspection Lot Record'!A:A,'QALS - Inspection Lot Record'!G:G) -> TP397880 | G35: =LOOKUP(A35,'QALS - Inspection Lot Record'!A:A,'QALS - Inspection Lot Record'!E:E) -> 45872 | H35: =IF(AND(P35<=O35,O35<=Q35),"A","R") -> A | I35: =F35 -> TP397880 | J35: =G35 -> 45872 | K35: =LOOKUP(A35,'QALS - Inspection Lot Record'!A:A,'QALS - Inspection Lot Record'!I:I) -> 0.54824074 | L35: =G35 -> 45872 | M35: =K35+TIME(0,RANDBETWEEN(25,50),RANDBETWEEN(0,59)) -> 0.57976852 | O35: 7.25 | P35: 3.5 | Q35: 11
A36: 40000002505 | B36: 1 | C36: =LOOKUP(A36,'QALS - Inspection Lot Record'!$A$2:$A$361,'QALS - Inspection Lot Record'!$O$2:$O$361) -> Metformin Tablets (500 MG) | D36: 30 | E36: Appearance | F36: =LOOKUP(A36,'QALS - Inspection Lot Record'!A:A,'QALS - Inspection Lot Record'!G:G) -> TP397880 | G36: =LOOKUP(A36,'QALS - Inspection Lot Record'!A:A,'QALS - Inspection Lot Record'!E:E) -> 45872 | H36: =IF(AND(P36<=O36,O36<=Q36),"A","R") -> A | I36: =F36 -> TP397880 | J36: =G36 -> 45872 | K36: =LOOKUP(A36,'QALS - Inspection Lot Record'!A:A,'QALS - Inspection Lot Record'!I:I) -> 0.54824074 | L36: =G36 -> 45872 | M36: =K36+TIME(0,RANDBETWEEN(25,50),RANDBETWEEN(0,59)) -> 0.58109954 | N36: Complies
A37: 40000002505 | B37: 1 | C37: =LOOKUP(A37,'QALS - Inspection Lot Record'!$A$2:$A$361,'QALS - Inspection Lot Record'!$O$2:$O$361) -> Metformin Tablets (500 MG) | D37: 40 | E37: Impurities | F37: =LOOKUP(A37,'QALS - Inspection Lot Record'!A:A,'QALS - Inspection Lot Record'!G:G) -> TP397880 | G37: =LOOKUP(A37,'QALS - Inspection Lot Record'!A:A,'QALS - Inspection Lot Record'!E:E) -> 45872 | H37: =IF(AND(P37<=O37,O37<=Q37),"A","R") -> A | I37: =F37 -> TP397880 | J37: =G37 -> 45872 | K37: =LOOKUP(A37,'QALS - Inspection Lot Record'!A:A,'QALS - Inspection Lot Record'!I:I) -> 0.54824074 | L37: =G37 -> 45872 | M37: =K37+TIME(0,RANDBETWEEN(25,50),RANDBETWEEN(0,59)) -> 0.57634259 | O37: 0 | P37: 0 | Q37: 2
A38: 40000002505 | B38: 1 | C38: =LOOKUP(A38,'QALS - Inspection Lot Record'!$A$2:$A$361,'QALS - Inspection Lot Record'!$O$2:$O$361) -> Metformin Tablets (500 MG) | D38: 50 | E38: Dissolution Rate - 15 Mins | F38: =LOOKUP(A38,'QALS - Inspection Lot Record'!A:A,'QALS - Inspection Lot Record'!G:G) -> TP397880 | G38: =LOOKUP(A38,'QALS - Inspection Lot Record'!A:A,'QALS - Inspection Lot Record'!E:E) -> 45872 | H38: =IF(AND(P38<=O38,O38<=Q38),"A","R") -> A | I38: =F38 -> TP397880 | J38: =G38 -> 45872 | K38: =LOOKUP(A38,'QALS - Inspection Lot Record'!A:A,'QALS - Inspection Lot Record'!I:I) -> 0.54824074 | L38: =G38 -> 45872 | M38: =K38+TIME(0,RANDBETWEEN(25,50),RANDBETWEEN(0,59)) -> 0.58297454 | O38: 50 | P38: 40 | Q38: 60
A39: 40000002505 | B39: 1 | C39: =LOOKUP(A39,'QALS - Inspection Lot Record'!$A$2:$A$361,'QALS - Inspection Lot Record'!$O$2:$O$361) -> Metformin Tablets (500 MG) | D39: 60 | E39: Dissolution Rate - 30 Mins | F39: =LOOKUP(A39,'QALS - Inspection Lot Record'!A:A,'QALS - Inspection Lot Record'!G:G) -> TP397880 | G39: =LOOKUP(A39,'QALS - Inspection Lot Record'!A:A,'QALS - Inspection Lot Record'!E:E) -> 45872 | H39: =IF(AND(P39<=O39,O39<=Q39),"A","R") -> A | I39: =F39 -> TP397880 | J39: =G39 -> 45872 | K39: =LOOKUP(A39,'QALS - Inspection Lot Record'!A:A,'QALS - Inspection Lot Record'!I:I) -> 0.54824074 | L39: =G39 -> 45872 | M39: =K39+TIME(0,RANDBETWEEN(25,50),RANDBETWEEN(0,59)) -> 0.58128472 | O39: 77.5 | P39: 70 | Q39: 85
A40: 40000002505 | B40: 1 | C40: =LOOKUP(A40,'QALS - Inspection Lot Record'!$A$2:$A$361,'QALS - Inspection Lot Record'!$O$2:$O$361) -> Metformin Tablets (500 MG) | D40: 70 | E40: Dissolution Rate - 40 Mins | F40: =LOOKUP(A40,'QALS - Inspection Lot Record'!A:A,'QALS - Inspection Lot Record'!G:G) -> TP397880 | G40: =LOOKUP(A40,'QALS - Inspection Lot Record'!A:A,'QALS - Inspection Lot Record'!E:E) -> 45872 | H40: =IF(AND(P40<=O40,O40<=Q40),"A","R") -> A | I40: =F40 -> TP397880 | J40: =G40 -> 45872 | K40: =LOOKUP(A40,'QALS - Inspection Lot Record'!A:A,'QALS - Inspection Lot Record'!I:I) -> 0.54824074 | L40: =G40 -> 45872 | M40: =K40+TIME(0,RANDBETWEEN(25,50),RANDBETWEEN(0,59)) -> 0.57407407 | O40: 85 | P40: 80 | Q40: 90
...

Sheet QAMR - Old
A1: Inspection Lot | B1: Node No | C1: Product Description | D1: Characteristic code | E1: Characteristic Desc | F1: Created by | G1: Created On | H1: Valuation | I1: Inspector | J1: StartDate | K1: StartTime | L1: EndDate | M1: EndTime | N1: Qualitative | O1: Quantative | P1: Min Value | Q1: Max Value
A2: 40000002201 | B2: 1 | C2: Ibuprofen Tables (100 MG) | D2: 10 | E2: Potency | F2: TG509538 | G2: 45406 | H2: A | I2: TG509538 | J2: 45406 | K2: 0.0069444444 | L2: 45406 | M2: 0.010416667 | O2: 98.5 | P2: 95 | Q2: 105
A3: 40000002201 | B3: 1 | C3: Ibuprofen Tables (100 MG) | D3: 20 | E3: PH Level | F3: TG509538 | G3: 45406 | H3: A | I3: TG509538 | J3: 45406 | K3: 0.013888889 | L3: 45406 | M3: 0.020833333 | O3: 6.2 | P3: 3.5 | Q3: 11.5
A4: 40000002201 | B4: 1 | C4: Ibuprofen Tables (100 MG) | D4: 30 | E4: Apperance | F4: TG509539 | G4: 45406 | H4: A | I4: TG509539 | J4: 45406 | K4: 0.020833333 | L4: 45406 | M4: 0.03125 | N4: Complies
A5: 40000002201 | B5: 1 | C5: Ibuprofen Tables (100 MG) | D5: 40 | E5: impurities | F5: TG509540 | G5: 45406 | H5: A | I5: TG509540 | J5: 45406 | K5: 0.027777778 | L5: 45406 | M5: 0.041666667 | O5: 0.5 | P5: 0 | Q5: 1
A6: 40000002201 | B6: 1 | C6: Ibuprofen Tables (100 MG) | D6: 50 | E6: Dissolution Rate (15 Mins) | F6: TG509541 | G6: 45406 | H6: A | I6: TG509541 | J6: 45406 | K6: 0.034722222 | L6: 45406 | M6: 0.052083333 | O6: 52.3 | P6: 40 | Q6: 60
A7: 40000002201 | B7: 1 | C7: Ibuprofen Tables (100 MG) | D7: 60 | E7: Dissolution Rate (30 Mins) | F7: TG509541 | G7: 45406 | H7: A | I7: TG509541 | J7: 45406 | K7: 0.041666667 | L7: 45406 | M7: 0.0625 | O7: 78.1 | P7: 70 | Q7: 85
A8: 40000002201 | B8: 1 | C8: Ibuprofen Tables (100 MG) | D8: 70 | E8: Dissolution Rate (40 Mins) | F8: TG509541 | G8: 45406 | P8: 80 | Q8: 90
A9: 40000002201 | B9: 1 | C9: Ibuprofen Tables (100 MG) | D9: 80 | E9: Process Temp | F9: TG509542 | G9: 45406 | H9: A | I9: TG509542 | J9: 45406 | K9: 0.055555556 | L9: 45406 | M9: 0.083333333 | O9: 25 | P9: 23 | Q9: 28
A10: 40000002351 | B10: 1 | C10: Metformin Tablets (100 MG) | D10: 10 | E10: Potency | F10: TG509542 | G10: 45400 | H10: A | I10: TG509541 | J10: 45400 | K10: 0.048611111 | L10: 45400 | M10: 0.054282407 | O10: 98.5 | P10: 95 | Q10: 105
A11: 40000002351 | B11: 1 | C11: Metformin Tablets (100 MG) | D11: 20 | E11: PH Level | F11: TG509542 | G11: 45400 | H11: A | I11: TG509541 | J11: 45400 | K11: 0.055555556 | L11: 45400 | M11: 0.10416667 | O11: 6.2 | P11: 3.5 | Q11: 11.5
A12: 40000002351 | B12: 1 | C12: Metformin Tablets (100 MG) | D12: 30 | E12: Apperance | F12: TG509542 | G12: 45400 | H12: A | I12: TG509541 | J12: 45400 | K12: 0.0625 | L12: 45400 | M12: 0.15405093 | N12: Complies
A13: 40000002351 | B13: 1 | C13: Metformin Tablets (100 MG) | D13: 40 | E13: impurities | F13: TG509542 | G13: 45400 | H13: A | I13: TG509541 | J13: 45400 | K13: 0.069444444 | L13: 45400 | M13: 0.20393519 | O13: 0.5 | P13: 0 | Q13: 1
A14: 40000002351 | B14: 1 | C14: Metformin Tablets (100 MG) | D14: 50 | E14: Dissolution Rate (15 Mins) | F14: TG509542 | G14: 45400 | H14: A | I14: TG509541 | J14: 45400 | K14: 0.076388889 | L14: 45400 | M14: 0.25381944 | O14: 54 | P14: 40 | Q14: 60
A15: 40000002351 | B15: 1 | C15: Metformin Tablets (100 MG) | D15: 60 | E15: Dissolution Rate (30 Mins) | F15: TG509542 | G15: 45400 | H15: A | I15: TG509541 | J15: 45400 | K15: 0.083333333 | L15: 45400 | M15: 0.3037037 | O15: 76 | P15: 70 | Q15: 85
A16: 40000002351 | B16: 1 | C16: Metformin Tablets (100 MG) | D16: 70 | E16: Dissolution Rate (40 Mins) | F16: TG509542 | G16: 45400 | H16: A | I16: TG509541 | J16: 45400 | K16: 0.090277778 | L16: 45400 | M16: 0.35358796 | O16: 82 | P16: 80 | Q16: 90
A17: 40000002351 | B17: 1 | C17: Metformin Tablets (100 MG) | D17: 80 | E17: Process Temp | F17: TG509542 | G17: 45400 | H17: A | I17: TG509541 | J17: 45400 | K17: 0.097222222 | L17: 45400 | M17: 0.40347222 | O17: 25 | P17: 23 | Q17: 25
A18: 40000002354 | B18: 1 | C18: Ibuprofen Tables (100 MG) | D18: 10 | E18: Potency | F18: TG509542 | G18: 45408 | H18: A | I18: TG509541 | J18: 45408 | K18: 0.090277778 | L18: 45408 | M18: 0.094444444 | O18: 98.5 | P18: 95 | Q18: 105
A19: 40000002354 | B19: 1 | C19: Ibuprofen Tables (100 MG) | D19: 20 | E19: PH Level | F19: TG509542 | G19: 45408 | H19: A | I19: TG509541 | J19: 45408 | K19: 0.09375 | L19: 45408 | M19: 0.10416667 | O19: 6.2 | P19: 3.5 | Q19: 11.5
A20: 40000002354 | B20: 1 | C20: Ibuprofen Tables (100 MG) | D20: 30 | E20: Apperance | F20: TG509542 | G20: 45408 | H20: A | I20: TG509541 | J20: 45408 | K20: 0.097222222 | L20: 45408 | M20: 0.11388889 | N20: Complies
A21: 40000002354 | B21: 1 | C21: Ibuprofen Tables (100 MG) | D21: 40 | E21: impurities | F21: TG509542 | G21: 45408 | H21: R | I21: TG509541 | J21: 45408 | K21: 0.10069444 | L21: 45408 | M21: 0.12361111 | O21: 1.2 | P21: 0 | Q21: 1
A22: 40000002354 | B22: 1 | C22: Ibuprofen Tables (100 MG) | D22: 50 | E22: Dissolution Rate (15 Mins) | F22: TG509542 | G22: 45408 | H22: A | I22: TG509541 | J22: 45408 | K22: 0.10416667 | L22: 45408 | M22: 0.13333333 | O22: 52.3 | P22: 40 | Q22: 60
A23: 40000002354 | B23: 1 | C23: Ibuprofen Tables (100 MG) | D23: 60 | E23: Dissolution Rate (30 Mins) | F23: TG509542 | G23: 45408 | H23: A | I23: TG509541 | J23: 45408 | K23: 0.10763889 | L23: 45408 | M23: 0.14305556 | O23: 78.1 | P23: 70 | Q23: 85
A24: 40000002354 | B24: 1 | C24: Ibuprofen Tables (100 MG) | D24: 70 | E24: Dissolution Rate (40 Mins) | F24: TG509542 | G24: 45408 | H24: A | I24: TG509541 | J24: 45408 | K24: 0.11111111 | L24: 45408 | M24: 0.15277778 | O24: 82 | P24: 80 | Q24: 90
A25: 40000002354 | B25: 1 | C25: Ibuprofen Tables (100 MG) | D25: 80 | E25: Process Temp | F25: TG509542 | G25: 45408 | H25: R | I25: TG509541 | J25: 45408 | K25: 0.11458333 | L25: 45408 | M25: 0.1625 | O25: 27 | P25: 23 | Q25: 25
A26: 40000002357 | B26: 1 | C26: Metformin Tablets (200 MG) | D26: 10 | E26: Potency | F26: TG509542 | G26: 45401 | H26: A | I26: TG509541 | J26: 45401 | K26: 0.12638889 | L26: 45401 | M26: 0.12986111 | O26: 98.5 | P26: 95 | Q26: 105
A27: 40000002357 | B27: 1 | C27: Metformin Tablets (200 MG) | D27: 20 | E27: PH Level | F27: TG509542 | G27: 45401 | H27: A | I27: TG509541 | J27: 45401 | K27: 0.12847222 | L27: 45401 | M27: 0.13541667 | O27: 6.2 | P27: 3.5 | Q27: 11.5
